Workbook

Sheet Insights Propostas
A1: Insights executivos — Propostas de Redução
A2: Origem: A.Propostas (103 propostas úteis, analisadas em 28/07/2026) | N2: Status | O2: Qtd. | P2: Potencial | R2: Checagem | S2: Valor
A3: A base monitora oportunidades de redução anual por código de material, planta, fonte/usina e status de avanço com Compras/Usina. O potencial total é R$ 3.380.894,04, com concentração relevante: os 5 maiores itens representam 28,5% do valor e o item líder sozinho representa 6,6%. JARINU concentra 56,0% do potencial total, enquanto S.U é a fonte/usina mais relevante por valor. O gargalo de execução está nas pendências: 16 itens somam R$ 903.321,85 e devem ser tratados antes de novas análises menos relevantes. | N3: SIM | O3: 62 | P3: 2719491.8 | R3: Linhas origem | S3: =COUNTA(A.Propostas!B6:B118) -> 106
N4: NÃO | O4: 37 | P4: 631869.95 | R4: Potencial origem | S4: =SUM(A.Propostas!F6:F118) -> 3426065.6
N5: N/A | O5: 1 | P5: 29532.29 | R5: SIM | S5: =COUNTIF(A.Propostas!Z6:Z118,"SIM") -> 70
N6: KAIZEN PLANO DE CORTE | O6: 3 | P6: 0 | R6: NÃO | S6: =COUNTIF(A.Propostas!Z6:Z118,"NÃO") -> 29
A7: Propostas | B7: Potencial total | C7: Potencial desbloqueável | D7: Top 5 / total | E7: Pendências | F7: Inviáveis | H7: Conclusão inicial | R7: KAIZEN | S7: =COUNTIF(A.Propostas!Z6:Z118,"KAIZEN PLANO DE CORTE") -> 0
A8: =COUNTA(A.Propostas!B6:B118) -> 106 | B8: =SUM(A.Propostas!F6:F118) -> 3426065.6 | C8: {=SUM(A.Propostas!F6:F118)-SUMPRODUCT(A.Propostas!F6:F118,--ISNUMBER(SEARCH("INVIÁVEL",A.Propostas!L6:L118&A.Propostas!AC6:AC118&A.Propostas!AK6:AK118)))} -> 2286855.5 | D8: {=SUM(LARGE(A.Propostas!F6:F118,{1,2,3,4,5}))/SUM(A.Propostas!F6:F118)} -> 0.26266249 | E8: {=SUMPRODUCT(--(MMULT(--ISNUMBER(SEARCH("PENDENTE",A.Propostas!AE6:AI118)),TRANSPOSE(COLUMN(A.Propostas!AE6:AI6)^0))>0))} -> 9 | F8: {=SUMPRODUCT(--ISNUMBER(SEARCH("INVIÁVEL",A.Propostas!L6:L118&A.Propostas!AC6:AC118&A.Propostas!AK6:AK118)))} -> 43 | H8: Atuar primeiro nos itens de maior valor e nos 16 casos pendentes pode acelerar a captura de R$ 903.321,85; a revisão dos 6 inviáveis evita esforço em R$ 438.060,56 com baixa probabilidade de captura.
N9: Planta | O9: Potencial
N10: JARINU | O10: 1894286.5
A11: Principais oportunidades e concentração | H11: Resumo por planta | N11: FERRAZ | O11: 987200.72
A12: Rank | B12: Código | C12: Planta | D12: Fonte | E12: Potencial | F12: % acumulado | H12: Planta | I12: Qtd. | J12: Potencial | K12: % total | L12: Ticket médio | N12: DIADEMA | O12: 499406.86
A13: 1 | B13: BOQ0800IS1200 | C13: FERRAZ | D13: ARCELOR | E13: 223577.79 | F13: 0.066129783 | H13: JARINU | I13: 80 | J13: 1894286.5 | K13: 0.56029158 | L13: 23678.581 | N13: SÃO LEPOLDO | O13: 0
A14: 2 | B14: BOQ1225BA1250 | C14: FERRAZ | D14: USIMINAS | E14: 214301.81 | F14: 0.12951592 | H14: FERRAZ | I14: 12 | J14: 987200.72 | K14: 0.29199398 | L14: 82266.727
A15: 3 | B15: BOQ1175AY1050 | C15: FERRAZ | D15: USIMINAS | E15: 190474.65 | F15: 0.18585446 | H15: DIADEMA | I15: 8 | J15: 499406.86 | K15: 0.14771444 | L15: 62425.857
A16: 4 | B16: SLZ0180SI0366 | C16: JARINU | D16: S.U | E16: 168140.89 | F16: 0.23558714 | H16: SÃO LEPOLDO | I16: 3 | J16: 0 | K16: 0 | L16: 0 | N16: Fonte/usina | O16: Potencial
A17: 5 | B17: BDZ0140SI03120950 | C17: JARINU | D17: GONVARRI | E17: 167489.23 | F17: 0.28512706 | N17: S.U | O17: 1390523.5
A18: 6 | B18: CHZ0180GZ05270841 | C18: DIADEMA | D18: S.U | E18: 128107.04 | F18: 0.32301853 | N18: USIMINAS | O18: 998683.29
A19: 7 | B19: BOQ0975AB1250 | C19: FERRAZ | D19: ARCELOR | E19: 117470.3 | F19: 0.35776386 | N19: ARCELOR | O19: 341048.09
A20: 8 | B20: BOQ0575LA1150 | C20: DIADEMA | D20: DE: USIMINAS PARA: ARCELOR | E20: 115000 | F20: 0.39177853 | N20: GONVARRI | O20: 194339.68
A21: 9 | B21: SLZ0180SI0325 | C21: JARINU | D21: S.U | E21: 113701.83 | F21: 0.42540923 | N21: CSN | O21: 164779.97
A22: 10 | B22: BDZ0140SI05750517 | C22: JARINU | D22: CSN | E22: 113597.52 | F22: 0.45900908 | N22: DE: USIMINAS PARA: ARCELOR | O22: 115000
N23: FERROLENE | O23: 105555.87
N24: VW - SU | O24: 70963.59
A25: Alertas e ações recomendadas | H25: Top fontes/usinas por valor
A26: Tema | B26: Qtd. | C26: Valor associado | D26: Insight / ação | H26: Fonte/usina | I26: Qtd. | J26: Potencial | K26: % total | L26: Ticket médio
A27: Pendências operacionais | B27: 16 | C27: 903321.85 | D27: Destravar plano de corte, cadastro, usina ou programação antes de abrir novas frentes. | H27: S.U | I27: 49 | J27: 1390523.5 | K27: 0.41128871 | L27: 28378.032 | N27: Rank | O27: Potencial | P27: % acumulado
A28: Itens inviáveis / declinados | B28: 6 | C28: 438060.56 | D28: Separar como baixo potencial de captura ou reavaliar somente se houver nova contraproposta técnica. | H28: USIMINAS | I28: 28 | J28: 998683.29 | K28: 0.2953903 | L28: 35667.261 | N28: 1 | O28: 223577.79 | P28: 0.066129783
A29: Sem redução potencial preenchida | B29: 11 | C29: 0 | D29: Completar valores para não subestimar o pipeline ou gerar ranking distorcido. | H29: ARCELOR | I29: 4 | J29: 341048.09 | K29: 0.10087512 | L29: 85262.023 | N29: 2 | O29: 214301.81 | P29: 0.12951592
A30: Kaizen / plano de corte | B30: 3 | C30: 0 | D30: Acompanhar como melhoria operacional; pode depender mais de engenharia/logística que de negociação. | H30: GONVARRI | I30: 5 | J30: 194339.68 | K30: 0.057481743 | L30: 38867.936 | N30: 3 | O30: 190474.65 | P30: 0.18585446
H31: CSN | I31: 7 | J31: 164779.97 | K31: 0.048738579 | L31: 23539.996 | N31: 4 | O31: 168140.89 | P31: 0.23558714
H32: DE: USIMINAS PARA: ARCELOR | I32: 1 | J32: 115000 | K32: 0.034014671 | L32: 115000 | N32: 5 | O32: 167489.23 | P32: 0.28512706
H33: FERROLENE | I33: 6 | J33: 105555.87 | K33: 0.031221288 | L33: 17592.644 | N33: 6 | O33: 128107.04 | P33: 0.32301853
H34: VW - SU | I34: 2 | J34: 70963.59 | K34: 0.020989593 | L34: 35481.795 | N34: 7 | O34: 117470.3 | P34: 0.35776386
N35: 8 | O35: 115000 | P35: 0.39177853
N36: 9 | O36: 113701.83 | P36: 0.42540923
N37: 10 | O37: 113597.52 | P37: 0.45900908
A39: Itens que merecem follow-up imediato
A40: Código | B40: Planta | C40: Fonte | D40: Potencial | E40: Status | F40: Motivo
A41: SLZ0180SI0366 | B41: JARINU | C41: S.U | D41: 168140.89 | E41: SIM | F41: Pendente em etapa operacional
...

Sheet Análise Propostas
A1: Análise de Propostas de Redução
A2: Base: A.Propostas, 103 propostas analisadas até 28/07/2026 | N2: Status | O2: Qtd. | Q2: Checks
A3: A planilha reúne propostas de redução potencial anual por material, com consumo médio, planta, fonte/usina e status de avanço com Compras/Usina. O potencial anual identificado soma R$ 3.380.894,04; os 5 maiores itens concentram 28,5% desse valor, indicando forte concentração do impacto. JARINU lidera o potencial por planta e S.U concentra o maior valor por fonte/usina. Há 0 propostas com prazo vencido sem retorno final registrado e 16 itens com pendências operacionais. | N3: SIM | O3: 62 | Q3: Total linhas | R3: =COUNTA(A.Propostas!B6:B118) -> 106
N4: NÃO | O4: 37 | Q4: Total potencial | R4: =SUM(A.Propostas!F6:F118) -> 3426065.6
N5: N/A | O5: 1 | Q5: SIM | R5: =COUNTIF(A.Propostas!Z6:Z118,"SIM") -> 70
A6: Propostas | B6: Potencial anual | C6: Média por proposta | D6: Enviadas à usina | E6: Pendências | F6: Prazos vencidos | H6: Leitura rápida | N6: KAIZEN PLANO DE CORTE | O6: 3 | Q6: NÃO | R6: =COUNTIF(A.Propostas!Z6:Z118,"NÃO") -> 29
A7: =COUNTA(A.Propostas!B6:B118) -> 106 | B7: =SUM(A.Propostas!F6:F118) -> 3426065.6 | C7: =B7/A7 -> 32321.374 | D7: =COUNTIF(A.Propostas!Z6:Z118,"SIM") -> 70 | E7: {=SUMPRODUCT(--(MMULT(--ISNUMBER(SEARCH("PENDENTE",A.Propostas!AE6:AI118)),TRANSPOSE(COLUMN(A.Propostas!AE6:AI6)^0))>0))} -> 9 | F7: {=SUMPRODUCT(--(A.Propostas!AB6:AB118<DATE(2026,7,28)),--(A.Propostas!AB6:AB118<>""),--(A.Propostas!AC6:AC118=""),--ISERROR(SEARCH("INVIÁVEL",A.Propostas!L6:L118&A.Propostas!AC6:AC118&A.Propostas!AK6:AK118)))} -> 0 | H7: Priorizar validação dos top itens e destravar pendências de plano/cadastro/programação: isso protege R$ 2.942.833,48 em oportunidades economicamente relevantes. | Q7: KAIZEN | R7: =COUNTIF(A.Propostas!Z6:Z118,"KAIZEN PLANO DE CORTE") -> 0
N9: Planta | O9: Potencial
A10: Top 10 oportunidades por redução potencial | H10: Resumo por planta | N10: JARINU | O10: 1894286.5
A11: Código | B11: Planta | C11: Fonte | D11: Status | E11: Redução potencial | F11: Histórico / observação | H11: Planta | I11: Qtd. | J11: Potencial | K11: % do total | L11: Ticket médio | N11: FERRAZ | O11: 987200.72
A12: BOQ0800IS1200 | B12: FERRAZ | C12: ARCELOR | D12: SIM | E12: 223577.79 | F12: INFOQM A SER LIBERADO. PROGRAMAÇÃO ENVIADA | H12: JARINU | I12: 80 | J12: 1894286.5 | K12: 0.56029158 | L12: 23678.581 | N12: DIADEMA | O12: 499406.86
A13: BOQ1225BA1250 | B13: FERRAZ | C13: USIMINAS | D13: SIM | E13: 214301.81 | F13: ALTERAÇÃO DE PART NUMBER (ESP.) CONSULTA REVISADA 2601342 TOLERANCIA ESP. | H13: FERRAZ | I13: 12 | J13: 987200.72 | K13: 0.29199398 | L13: 82266.727 | N13: SÃO LEPOLDO | O13: 0
A14: BOQ1175AY1050 | B14: FERRAZ | C14: USIMINAS | D14: SIM | E14: 190474.65 | F14: ALTERAÇÃO DE PART NUMBER (ESP.) | H14: DIADEMA | I14: 8 | J14: 499406.86 | K14: 0.14771444 | L14: 62425.857
A15: SLZ0180SI0366 | B15: JARINU | C15: S.U | D15: SIM | E15: 168140.89 | F15: ITEM ENVIADO NO PRIMEIRO PACOTE DE SOLICITAÇÕES DE MODIFICAÇÕES | H15: SÃO LEPOLDO | I15: 3 | J15: 0 | K15: 0 | L15: 0
A16: BDZ0140SI03120950 | B16: JARINU | C16: GONVARRI | D16: NÃO | E16: 167489.23 | N16: Fonte | O16: Potencial
A17: CHZ0180GZ05270841 | B17: DIADEMA | C17: S.U | D17: SIM | E17: 128107.04 | N17: S.U | O17: 1390523.5
A18: BOQ0975AB1250 | B18: FERRAZ | C18: ARCELOR | D18: SIM | E18: 117470.3 | F18: CRIAÇÃO DE CÓDIGO EM ANDAMENTO | N18: USIMINAS | O18: 998683.29
A19: BOQ0575LA1150 | B19: DIADEMA | C19: DE: USIMINAS PARA: ARCELOR | D19: SIM | E19: 115000 | F19: ENVIADO CONFIRMAÇÃO PARA ENG. | N19: ARCELOR | O19: 341048.09
A20: SLZ0180SI0325 | B20: JARINU | C20: S.U | D20: SIM | E20: 113701.83 | F20: ITEM ENVIADO NO PRIMEIRO PACOTE DE SOLICITAÇÕES DE MODIFICAÇÕES | N20: GONVARRI | O20: 194339.68
A21: BDZ0140SI05750517 | B21: JARINU | C21: CSN | D21: NÃO | E21: 113597.52 | N21: CSN | O21: 164779.97
N22: DE: USIMINAS PARA: ARCELOR | O22: 115000
N23: FERROLENE | O23: 105555.87
N24: VW - SU | O24: 70963.59
A25: Alertas operacionais | H25: Top fontes/usinas por potencial
A26: Tipo | B26: Qtd. | C26: Potencial associado | D26: Comentário | H26: Fonte/usina | I26: Qtd. | J26: Potencial | K26: % do total | L26: Ticket médio
A27: Prazos vencidos | B27: 0 | C27: 0 | D27: Prazo de usina/cadastro/recebimento anterior a 28/07/2026 sem devolução válida. | H27: S.U | I27: 49 | J27: 1390523.5 | K27: 0.41128871 | L27: 28378.032
A28: Pendências de plano/cadastro/programação | B28: 16 | C28: 903321.85 | D28: Itens marcados como PENDENTE em plano, usina, cadastro ou programação. | H28: USIMINAS | I28: 28 | J28: 998683.29 | K28: 0.2953903 | L28: 35667.261
A29: Itens inviáveis/contra-proposta declinada | B29: 6 | C29: 438060.56 | D29: Histórico ou retorno indica inviabilidade metalúrgica/técnica. | H29: ARCELOR | I29: 4 | J29: 341048.09 | K29: 0.10087512 | L29: 85262.023
A30: Kaizen/plano de corte | B30: 3 | C30: 0 | D30: Itens classificados como plano de corte, normalmente dependentes de validação operacional. | H30: GONVARRI | I30: 5 | J30: 194339.68 | K30: 0.057481743 | L30: 38867.936
H31: CSN | I31: 7 | J31: 164779.97 | K31: 0.048738579 | L31: 23539.996
H32: DE: USIMINAS PARA: ARCELOR | I32: 1 | J32: 115000 | K32: 0.034014671 | L32: 115000
A33: Itens críticos para follow-up | H33: FERROLENE | I33: 6 | J33: 105555.87 | K33: 0.031221288 | L33: 17592.644
A34: Código | B34: Planta | C34: Fonte | D34: Prazo/retorno | E34: Potencial | F34: Motivo | H34: VW - SU | I34: 2 | J34: 70963.59 | K34: 0.020989593 | L34: 35481.795
A35: SLZ0180SI0366 | B35: JARINU | C35: S.U | D35: 2026-03-27T00:00:00.000Z | E35: 168140.89 | F35: Pendência operacional | H35: GONVARRI FERROLENE | I35: 1 | J35: 0 | K35: 0 | L35: 0
A36: BOQ0975AB1250 | B36: FERRAZ | C36: ARCELOR | D36: 2026-06-20T00:00:00.000Z | E36: 117470.3 | F36: Pendência operacional
A37: SLZ0180SI0325 | B37: JARINU | C37: S.U | D37: 2026-03-27T00:00:00.000Z | E37: 113701.83 | F37: Pendência operacional
A38: SLZ0180SI0466 | B38: JARINU | C38: S.U | D38: 2026-04-06T00:00:00.000Z | E38: 110915.64 | F38: Pendência operacional
A39: BOF0100TR1350 | B39: JARINU | C39: S.U | D39: 2026-08-03T00:00:00.000Z | E39: 96985.81 | F39: Pendência operacional
A40: SLZ0150SI0725 | B40: JARINU | C40: S.U | D40: 2026-03-27T00:00:00.000Z | E40: 77871.276 | F40: Pendência operacional
A41: BOZ0120UI0950 | B41: JARINU | C41: S.U | D41: 2026-08-03T00:00:00.000Z | E41: 76712.125 | F41: Pendência operacional
...

Sheet Controle
A2: Código Bobina Mâe | B2: Tipo | C2: Esp. (mm) | D2: Larg (mm) | E2: Compr (mm) | F2: Tolerância + - | G2: Descrição | H2: Cód no Fornecedor | I2: Grupo | J2: LT (dias) | K2: Lote Múltiplo [Usina] Lote Mínimo [Distrib] Ton | L2: Usina Referência | M2: Cliente | N2: Projeto | O2: ABC | P2: CORTE | Q2: FATURAMENTO PEÇA | R2: Unidade Delga | S2: Beneficiador | T2: NECESSIDADE Janeiro / 2026 | U2: NECESSIDADE Fevereiro / 2026 | V2: NECESSIDADE Março / 2026 | W2: NECESSIDADE Abril / 2026 | X2: NECESSIDADE Maio / 2026 | Y2: NECESSIDADE MÉDIA FEV A MAIO (ton) | Z2: Análise espessura | AA2: Análise Largura | AB2: Análise Comprimento / passo | AC2: Análise da qualidade | AD2: Análise Plano de corte / nest | AE2: Análise de estoque | AF2: Outros | AG2: Concluido análise | AH2: V. Médio Análisado | AI2: Quantidade de produtos relacionados | AJ2: Produtos relacionados | AK2: Ganho MENSAL | AL2: Código nova bobina | AM2: OBS | AN2: Primeiro Ganho previsto | AO2: Validado (USINA/CUSTOS)
A3: CHZ0180GZ07301920 | B3: BZ | C3: 1.8 | D3: 1100 | E3: - | F3: ±0,13 | G3: EN10346 HX300YDZ100 1,80X1100 M10441430 | H3: 34029156 | L3: VW - SU | M3: VW-SBC | N3: Saveiro | O3: A | P3: Diadema | Q3: Diadema | R3: Diadema | S3: Diadema | T3: 194.52238 | U3: 211.84826 | V3: 213.42334 | W3: 127.58148 | X3: 189.0096 | Y3: =AVERAGE(T3:X3) -> 187.27701 | Z3: X | AA3: X | AB3: X | AC3: X | AD3: X | AE3: X | AF3: X | AG3: =COUNTIF(Z3:AF3,"X")/7 -> 1 | AH3: =IF(AG3=100%,Y3," ") -> 187.27701 | AI3: 2 | AJ3: VW000573Z / 574Z | AK3: 0 | AM3: Longarina da Saveiro, em análise na possibilidade de redução do comprimento do blank (passo de corte no fornecedor).
A4: BOQ0475ED1250 | B4: BQ | C4: 4.75 | D4: 1250 | E4: - | F4: ±0,10 | G4: BOB NBR6656 LNE38 D/O 4,75X1250 | H4: - | L4: USIMINAS | M4: ANCHIETA /MAN/FAURECIA | N4: Travessas 73/74 , 0038 e itens MAN | O4: A | P4: Diadema | Q4: Diadema | R4: Diadema | S4: Ferrolene | T4: 67.237324 | U4: 68.395356 | V4: 89.373864 | W4: 82.735722 | X4: 82.275846 | Y4: =AVERAGE(T4:X4) -> 78.003622 | Z4: X | AA4: X | AB4: X | AC4: X | AD4: X | AE4: X | AF4: X | AG4: =COUNTIF(Z4:AF4,"X")/7 -> 1 | AH4: =IF(AG4=100%,Y4," ") -> 78.003622 | AI4: 25 | AJ4: FA000007AA / FA000008AA / PU000008AA / MB000073AX / MB000074AX / DA000458Z / VW001141AA / VW001142AA / VW001143AA / VW001155AA / DA000525LA / DA000525LB / DA000525LC / DA000525LH / DA000525LI / MB003533LA / MB003533LB / MB003536LA / MB003536LB / MB003537LA / MB003537LB / MB003538LA / MB003538LB / MB003673LC / MB002316LA | AK4: 43147.96 | AM4: Produtos com processo de corte laser com reduções significativas no peso bruto unitário. DA000458Z - Redução de 12mm na largura do blank. De 300mm para 288mm. Redução de 0,44kg por blank. Os produtos "Travessa" da MBB estão em análise (MB000073AX / 074AX). | AN4: 46082 | AO4: Sim
A5: BOQ0285EE0885 | B5: BQ | C5: 2.85 | D5: 885 | E5: - | F5: 2,85 MTH | G5: NBR-6656-16-LNE-500 | H5: - | L5: USIMINAS | M5: ANCHIETA / VOLVO | N5: Projeto Fuel Tank - Projeto Especial ( VOLVO) | O5: A | P5: Diadema | Q5: Diadema | R5: Diadema | S5: Diadema | T5: 75.627 | U5: 67.224 | V5: 73.509444 | W5: 75.324492 | X5: 76.837032 | Y5: =AVERAGE(T5:X5) -> 73.704394 | Z5: X | AA5: X | AB5: X | AC5: X | AD5: X | AE5: X | AF5: X | AG5: =COUNTIF(Z5:AF5,"X")/7 -> 1 | AH5: =IF(AG5=100%,Y5," ") -> 73.704394 | AI5: 1 | AJ5: DA000459AA | AK5: 4163.27 | AM5: Redução no passo (Comprimento) do blank. | AN5: 46143 | AO5: Sim
A6: SLZ0120UI0500 | B6: SLZ | C6: 1.2 | D6: 500 | E6: - | G6: BOB VW50065 CR3-GI40/40-U-O 1,20X1250MM | H6: 34025664 | L6: SOLUÇÕES USIMINAS | M6: VW-SBC /TBT | N6: Nivus/Polo | O6: A | P6: Diadema | Q6: Diadema | R6: Diadema | S6: Diadema | T6: 54.7344 | U6: 52.4538 | V6: 54.7344 | W6: 48.6528 | X6: 72.9792 | Y6: =AVERAGE(T6:X6) -> 56.71092 | Z6: X | AA6: X | AB6: X | AC6: X | AD6: X | AE6: X | AF6: X | AG6: =COUNTIF(Z6:AF6,"X")/7 -> 1 | AH6: =IF(AG6=100%,Y6," ") -> 56.71092 | AI6: 2 | AJ6: VW000895AA / 896AA | AK6: 0 | AM6: Material em análise. Oportunidade de redução de 10mm no passo de corte do desbobinador (interno) - De 265mm para 255mm
A7: CHF0100HA06250872 | B7: BF | C7: 1 | D7: 1350 | E7: 315 | F7: 0.075 | G7: BOB EN10268 HC260LA 1,00X1250 M10440489 | H7: M10440489 | L7: FERROLENE | M7: VW-SBC | N7: Saveiro | O7: A | P7: Diadema | Q7: Diadema | R7: Diadema | S7: Diadema | T7: 53.573212 | U7: 60.627336 | V7: 61.00864 | W7: 36.414532 | X7: 54.240494 | Y7: =AVERAGE(T7:X7) -> 53.172843 | Z7: X | AA7: X | AB7: X | AC7: X | AD7: X | AE7: X | AF7: X | AG7: =COUNTIF(Z7:AF7,"X")/7 -> 1 | AH7: =IF(AG7=100%,Y7," ") -> 53.172843 | AI7: 2 | AJ7: VW000630AC / 631AC | AK7: 0 | AM7: "Pulmão" da Saveiro, sem proposta de KAIZEN.
A8: CHF0180SF07500640 | B8: CHF | C8: 1.8 | D8: 750 | E8: 640 | G8: BOB DIN EN10130 + A1 DC01 Am 1,80X1500MM | H8: 34025705 | L8: SOLUÇÕES USIMINAS | M8: VW-SBC | N8: Saveiro | O8: A | P8: Diadema | Q8: Diadema | R8: Sul | S8: Diadema | T8: 41.85472 | U8: 47.74054 | V8: 48.39452 | W8: 29.4291 | X8: 42.5087 | Y8: =AVERAGE(T8:X8) -> 41.985516 | Z8: X | AA8: X | AB8: X | AC8: X | AD8: X | AE8: X | AF8: X | AG8: =COUNTIF(Z8:AF8,"X")/7 -> 1 | AH8: =IF(AG8=100%,Y8," ") -> 41.985516 | AI8: 2 | AJ8: VW000745Z / 746Z | AK8: =16000/12 -> 1333.3333 | AM8: Processo terceirizado para Delga SUL. | AO8: Sim
A9: BOQ0575LN1200 | B9: BQ | C9: 1.8 | D9: 366 | E9: 840 | F9: 0.075 | G9: EN-10149-2-13-S420MC | H9: - | L9: ARCELOR | M9: ANCHIETA / SCANIA | N9: AD 5699-22 ( Telha e Chifre) | O9: A | P9: Diadema | Q9: Diadema | R9: Diadema | S9: Ferrolene | T9: 24.0702 | U9: 42.526632 | V9: 48.189152 | W9: 36.419424 | X9: 42.402072 | Y9: =AVERAGE(T9:X9) -> 38.721496 | Z9: X | AA9: X | AB9: X | AC9: X | AD9: X | AE9: X | AF9: X | AG9: =COUNTIF(Z9:AF9,"X")/7 -> 1 | AH9: =IF(AG9=100%,Y9," ") -> 38.721496 | AI9: 2 | AJ9: SV001141LA / SV001142LA | AK9: 20109.23 | AM9: Produtos com processo de corte laser com reduções significativas no peso bruto unitário. Os produtos "Travessa" da MBB estão em análise. | AN9: 46113 | AO9: Sim
A10: BOF0100UQ1200 | B10: BF | C10: 1 | D10: 1200 | E10: - | F10: ±0,04 | G10: GMW3399M-ST-S-CR980T/700Y-MP-LCE-UNC | H10: - | L10: USIMINAS | M10: GM/JARINU | N10: TRACKER | O10: A | P10: Diadema | Q10: Diadema | R10: Diadema | S10: Diadema | T10: 31.9365 | U10: 32.148 | V10: 55.33968 | W10: 31.02 | X10: 34.7424 | Y10: =AVERAGE(T10:X10) -> 37.037316 | Z10: X | AA10: X | AB10: X | AC10: X | AD10: X | AE10: X | AF10: X | AG10: =COUNTIF(Z10:AF10,"X")/7 -> 1 | AH10: =IF(AG10=100%,Y10," ") -> 37.037316 | AI10: 2 | AJ10: DJ000059Z / 060Z | AK10: 21877.25 | AM10: Redução no passo (Comprimento) do blank. | AN10: 46113 | AO10: Sim
A11: CHZ0180GZ05270841 | B11: BZ | C11: 1.8 | D11: 1450 | E11: - | F11: ±0,14 | G11: EN10292 HX300YD Z100 | H11: 34029203 | L11: VW - SU | M11: VW-SBC | N11: Saveiro | O11: A | P11: Diadema | Q11: Diadema | R11: Diadema | S11: Diadema | T11: 34.166407 | U11: 40.1718 | V11: 43.665 | W11: 13.9728 | X11: 47.1582 | Y11: =AVERAGE(T11:X11) -> 35.826841 | Z11: X | AA11: X | AB11: X | AC11: X | AD11: X | AE11: X | AF11: X | AG11: =COUNTIF(Z11:AF11,"X")/7 -> 1 | AH11: =IF(AG11=100%,Y11," ") -> 35.826841 | AI11: 2 | AJ11: VW00581Z / 582Z | AK11: 18301.01 | AM11: Redução no passo (Comprimento) do blank. Aguardando retorno de compras referente à MP. | AN11: 46174
A12: CHF0180SF04000900 | B12: CHF | C12: 1.8 | D12: 400 | E12: 900 | G12: BOB DIN EN10130 + A1 DC01 Am 1,80X1200MM | H12: 34025704 | L12: SOLUÇÕES USIMINAS | M12: VW-SBC | N12: Saveiro | O12: A | P12: Diadema | Q12: Diadema | R12: Diadema | S12: Diadema | T12: 33.788052 | U12: 35.5025 | V12: 38.0845 | W12: 16.783 | X12: 36.7935 | Y12: =AVERAGE(T12:X12) -> 32.19031 | Z12: X | AA12: X | AB12: X | AC12: X | AD12: X | AE12: X | AF12: X | AG12: =COUNTIF(Z12:AF12,"X")/7 -> 1 | AH12: =IF(AG12=100%,Y12," ") -> 32.19031 | AI12: 2 | AJ12: VW000585Z / 586Z | AK12: 5385.33 | AM12: Reduzir 20mm no passo do blank, de 900 para 880 (10mm/peça). Aguardando validação da controladoria. | AN12: 46204 | AO12: Sim
A13: CHZ0100SE12000540 | B13: BZ | C13: 1.8 | D13: 325 | E13: 630 | F13: 0.075 | G13: VW50065 - CR3-GI40/40 | H13: M10441440 | L13: FERROLENE | M13: VW-SBC | N13: Saveiro | O13: A | P13: Diadema | Q13: Diadema | R13: Diadema | S13: Diadema | T13: 33.5595 | U13: 36.141 | V13: 36.39915 | W13: 21.6846 | X13: 32.26875 | Y13: =AVERAGE(T13:X13) -> 32.0106 | Z13: X | AA13: X | AB13: X | AC13: X | AD13: X | AE13: X | AF13: X | AG13: =COUNTIF(Z13:AF13,"X")/7 -> 1 | AH13: =IF(AG13=100%,Y13," ") -> 32.0106 | AI13: 4 | AJ13: VW000522AA | AK13: 0 | AM13: Material analisado e sem oportunidade de redução.
A14: BOZ0065HV1050 | B14: BZ | C14: 0.65 | D14: 1050 | E14: - | G14: GMW2M-ST-S-CR3-HD60G60G-U 0,65X1050 | H14: - | L14: USIMINAS | M14: GM/JARINU | O14: A | P14: Diadema | Q14: Diadema | R14: Diadema | S14: Diadema | T14: 25.18512 | U14: 33.34776 | V14: 38.93648 | W14: 30.33296 | X14: 31.62384 | Y14: =AVERAGE(T14:X14) -> 31.885232 | Z14: X | AA14: X | AB14: X | AC14: X | AD14: X | AE14: X | AF14: X | AG14: =COUNTIF(Z14:AF14,"X")/7 -> 1 | AH14: =IF(AG14=100%,Y14," ") -> 31.885232 | AI14: 6 | AJ14: GM000378Z / 379Z / GM000396Z / 397Z / GM000380Z / 381Z | AK14: 6282.89 | AM14: Reduzir 20mm no passo do blank, de 240 para 220 (10mm/peça). | AN14: 46204 | AO14: Sim
A15: BOQ0630IH1300 | B15: BQ | C15: 6.3 | D15: 1200 | E15: - | G15: CHQ NBR6656 LNE28 6,00X1200X2000 | H15: - | L15: ARCELOR | M15: ANCHIETA | N15: MBB | O15: A | P15: Diadema | Q15: Diadema | R15: Diadema | S15: Ferrolene | T15: 28.061085 | U15: 27.69159 | V15: 36.252684 | W15: 33.39063 | X15: 33.39063 | Y15: =AVERAGE(T15:X15) -> 31.757324 | Z15: X | AA15: X | AB15: X | AC15: X | AD15: X | AE15: X | AF15: X | AG15: =COUNTIF(Z15:AF15,"X")/7 -> 1 | AH15: =IF(AG15=100%,Y15," ") -> 31.757324 | AI15: 1 | AJ15: DA000503Z | AK15: 0 | AM15: Material em análise (Izaias Claro). Possibilidade na redução da largura da bobina / chapa.
A16: BOZ0150HX1000 | B16: BZ | C16: 1.5 | D16: 1000 | E16: - | F16: NÃO | G16: GMW3032M-ST-S-340LA-HD60G60G-U 1,5X1000 | H16: - | L16: USIMINAS | M16: GM/JARINU | N16: TRACKER | O16: A | P16: Diadema | Q16: Diadema | R16: Diadema | S16: Diadema | T16: 26.85094 | U16: 29.996158 | V16: 38.147038 | W16: 31.483694 | X16: 27.1762 | Y16: =AVERAGE(T16:X16) -> 30.730806 | Z16: X | AA16: X | AB16: X | AC16: X | AD16: X | AE16: X | AF16: X | AG16: =COUNTIF(Z16:AF16,"X")/7 -> 1 | AH16: =IF(AG16=100%,Y16," ") -> 30.730806 | AI16: 6 | AJ16: GM000390Z / GM000391Z / GM000392Z / GM000393Z / DJ000131Z / DJ000132Z | AK16: 8657.01 | AM16: Redução da largura do slitter de 1000mm para 950mm | AN16: 46235 | AO16: Sim
A17: CHF0120TL02100570 | B17: CHF | C17: 1.2 | D17: 210 | E17: 570 | G17: BO VW50065 CR300LA UC 1,20X1050MM | H17: 34025707 | L17: SOLUÇÕES USIMINAS | M17: JARINU | N17: POLO / VIRTUS PA / NIVUS | O17: A | P17: Diadema | Q17: Diadema | R17: Diadema | S17: Diadema | T17: 30.581408 | U17: 26.40352 | V17: 31.07104 | W17: 32.44384 | X17: 31.52864 | Y17: =AVERAGE(T17:X17) -> 30.40569 | Z17: X | AA17: X | AB17: X | AC17: X | AD17: X | AE17: X | AF17: X | AG17: =COUNTIF(Z17:AF17,"X")/7 -> 1 | AH17: =IF(AG17=100%,Y17," ") -> 30.40569 | AI17: 4 | AJ17: DJ000049Z / DJ000050Z / DJ000232Z / DJ000233Z | AK17: 0 | AM17: Item da transfer (Cattaneo).
A18: BOQ0800ZN1300 | B18: BQ | C18: 1.5 | D18: 725 | E18: 70 | F18: 0.075 | G18: BOQ EN10149-2 S500MC 8,00X1300 | H18: - | L18: USIMINAS | M18: ANCHIETA / MBB / SCANIA | N18: MBB Boomerang / Scania Facão | O18: A | P18: Diadema | Q18: Diadema | R18: Diadema | S18: Ferrolene | T18: 22.626375 | U18: 26.80724 | V18: 33.201522 | W18: 31.318612 | X18: 31.10569 | Y18: =AVERAGE(T18:X18) -> 29.011888 | Z18: X | AA18: X | AB18: X | AC18: X | AD18: X | AE18: X | AF18: X | AG18: =COUNTIF(Z18:AF18,"X")/7 -> 1 | AH18: =IF(AG18=100%,Y18," ") -> 29.011888 | AI18: 10 | AJ18: VB000347LA / DA000496Z / DA000498Z / DA000499Z / DA000501Z / DA000500Z / DA000502Z / DA000506Z / DA000530Z / DA000531 | AK18: 0 | AM18: "Facão" da Volvo e Boomerangs da MBB sem oportunidades de redução.
A19: BOZ0100CN1200 | B19: BZ | C19: 1 | D19: 1200 | E19: - | G19: BOB EN10327 DX53 Z100 1,00X1200 MM **1100mm** | H19: - | L19: USIMINAS | M19: MERCEDES | N19: Lâmina | O19: A | P19: Diadema | Q19: Diadema | R19: Diadema | S19: Ferrolene | T19: 22.825968 | U19: 27.861108 | V19: 34.361016 | W19: 27.861108 | X19: 31.309416 | Y19: =AVERAGE(T19:X19) -> 28.843723 | Z19: X | AA19: X | AB19: X | AC19: X | AD19: X | AE19: X | AF19: X | AG19: =COUNTIF(Z19:AF19,"X")/7 -> 1 | AH19: =IF(AG19=100%,Y19," ") -> 28.843723 | AI19: 1 | AJ19: DA000213Z | AK19: 10148.41 | AM19: KAIZEN de redução na largura ainda não implementado (de 1200mm para 1100mm) | AN19: 46296 | AO19: Sim
A20: SLZ0180SI0285 | B20: SLZ | C20: 1.8 | D20: 285 | E20: - | G20: BO VW50065 CR300LA-GI40/40U 1,80X1150MM | H20: 34026257 | L20: SOLUÇÕES USIMINAS | M20: VW-SBC | N20: Polo/Virtus/Nivus | O20: A | P20: Diadema | Q20: Diadema | R20: Diadema | S20: Diadema | T20: 24.737442 | U20: 25.4849 | V20: 31.7261 | W20: 27.5653 | X20: 31.206 | Y20: =AVERAGE(T20:X20) -> 28.143948 | AF20: X | AG20: =COUNTIF(Z20:AF20,"X")/7 -> 0.14285714 | AH20: =IF(AG20=100%,Y20," ") | AI20: 2 | AJ20: VW000887AA / VW000888AA | AK20: 0 | AM20: Material em análise. Oportunidade de redução no passo de corte do desbobinador (interno) - Item da Cattaneo
A21: BOQ0375PQ1550 | B21: BQ | C21: 0.7 | D21: 675 | E21: 1600 | F21: 0.055 | G21: EN10149-2 S460MC 3,75MTH x 1550 | H21: - | L21: ARCELOR | M21: FERRAZ | N21: Suporte do tanque (Scania) | O21: A | P21: Jarinu | Q21: Diadema | R21: Diadema | S21: Ferrolene | T21: 13.4316 | U21: 28.782 | V21: 37.638 | W21: 26.568 | X21: 30.258 | Y21: =AVERAGE(T21:X21) -> 27.33552 | Z21: X | AA21: X | AB21: X | AC21: X | AD21: X | AE21: X | AF21: X | AG21: =COUNTIF(Z21:AF21,"X")/7 -> 1 | AH21: =IF(AG21=100%,Y21," ") -> 27.33552 | AI21: 2 | AJ21: DA000489AA / DA000490AA | AK21: 56402.8 | AM21: Redução de 20mm no blank (0,46kg)/peça | AN21: 46143 | AO21: Sim
A22: CHF0275KO06400290 | B22: BF | C22: 2.75 | D22: 1280 | E22: - | G22: EN10130 DC03 A | H22: 34029201 | L22: VW - SU | M22: VW-SBC | N22: Saveiro | O22: B | P22: Diadema | Q22: Diadema | R22: Diadema | S22: Diadema | T22: 26.598 | U22: 28.644 | V22: 30.69 | W22: 10.23 | X22: 31.713 | Y22: =AVERAGE(T22:X22) -> 25.575 | Z22: X | AA22: X | AB22: X | AC22: X | AD22: X | AE22: X | AF22: X | AG22: =COUNTIF(Z22:AF22,"X")/7 -> 1 | AH22: =IF(AG22=100%,Y22," ") -> 25.575 | AI22: 2 | AJ22: VW000583Z / VW000584Z | AK22: 0 | AM22: MP analisada com oportunidade de redução no comprimento e largura do blank (Redução de 30mm no comprimento e 5mm na largura)
A23: BOQ0700IS1300 | B23: BQ | C23: 7 | D23: 1300 | E23: - | G23: 6656 LNE50 7,0(+0/-0,3 MTL)X1300 | H23: - | L23: ARCELOR | M23: FERRAZ | N23: MBB | O23: B | P23: Diadema | Q23: Diadema | R23: Diadema | S23: Ferrolene | T23: 23.10912 | U23: 21.74976 | V23: 28.32673 | W23: 26.50752 | X23: 25.14816 | Y23: =AVERAGE(T23:X23) -> 24.968258 | Z23: X | AA23: X | AB23: X | AC23: X | AD23: X | AE23: X | AF23: X | AG23: =COUNTIF(Z23:AF23,"X")/7 -> 1 | AH23: =IF(AG23=100%,Y23," ") -> 24.968258 | AI23: 1 | AJ23: MB003601Z | AK23: 486.53 | AM23: Redução do peso bruto da chapa com 24 peças / chapa. | AN23: 46143 | AO23: Sim
A24: BOF0130UQ0950 | B24: BF | C24: 1.3 | D24: 950 | E24: - | G24: GMW3399M-ST-S-CR980T/700Y-MP-LCE-UNC | H24: - | L24: USIMINAS | M24: GM/JARINU | N24: TRACKER | O24: B | P24: Diadema | Q24: Diadema | R24: Diadema | S24: Diadema | T24: 13.65024 | U24: 21.956064 | V24: 37.565152 | W24: 21.254272 | X24: 23.860928 | Y24: =AVERAGE(T24:X24) -> 23.657331 | Z24: X | AA24: X | AB24: X | AC24: X | AD24: X | AE24: X | AF24: X | AG24: =COUNTIF(Z24:AF24,"X")/7 -> 1 | AH24: =IF(AG24=100%,Y24," ") -> 23.657331 | AI24: 2 | AJ24: DJ000055Z / DJ000056Z | AK24: 0
A25: CHZ0250SE02900636 | B25: BZ | C25: 2.5 | D25: 1160 | E25: - | G25: EN10346 DX54DZ100MBO 2,50X1160 M10441443 | H25: 34028996 | L25: VW - SU | M25: VW-SBC | N25: Saveiro | O25: B | P25: Diadema | Q25: Diadema | R25: Diadema | S25: Diadema | T25: 26.507115 | U25: 24.7968 | V25: 28.3392 | W25: 8.856 | X25: 28.3392 | Y25: =AVERAGE(T25:X25) -> 23.367663 | Z25: X | AA25: X | AB25: X | AC25: X | AD25: X | AE25: X | AF25: X | AG25: =COUNTIF(Z25:AF25,"X")/7 -> 1 | AH25: =IF(AG25=100%,Y25," ") -> 23.367663 | AI25: 2 | AJ25: VW000589Z / VW000590Z | AK25: 0 | AM25: Material analisado e sem oportunidade de redução.
A26: BOF0150ZM1050 | B26: BF | C26: 1.5 | D26: 1050 | E26: - | H26: - | L26: USIMINAS | M26: ANCHIETA / SCANIA | N26: Cintas Scania | O26: B | P26: Diadema | Q26: Diadema | R26: Diadema | S26: Ferrolene | T26: 9.0986 | U26: 17.47872 | V26: 29.5674 | W26: 29.45172 | X26: 29.46108 | Y26: =AVERAGE(T26:X26) -> 23.011504 | Z26: X | AA26: X | AB26: X | AC26: X | AD26: X | AE26: X | AF26: X | AG26: =COUNTIF(Z26:AF26,"X")/7 -> 1 | AH26: =IF(AG26=100%,Y26," ") -> 23.011504 | AI26: 5 | AJ26: DA000475AA / DA000476AA / DA000477AA / DA000478AA / DA000479AA | AK26: 0 | AM26: Material analisado e sem oportunidade de redução - Sendo analisado perda de uma sobra de sleeter.
A27: BOF0120AI1300 | B27: BF | C27: 1.2 | D27: 1300 | E27: - | G27: NBR5915 LF EP | H27: - | L27: USIMINAS | M27: MERCEDES | N27: Lateral | O27: B | P27: Diadema | Q27: Diadema | R27: Diadema | S27: Diadema | T27: 15.5375 | U27: 21.131 | V27: 27.346 | W27: 24.86 | X27: 24.86 | Y27: =AVERAGE(T27:X27) -> 22.7469 | Z27: X | AA27: X | AB27: X | AC27: X | AD27: X | AE27: X | AF27: X | AG27: =COUNTIF(Z27:AF27,"X")/7 -> 1 | AH27: =IF(AG27=100%,Y27," ") -> 22.7469 | AI27: 2 | AJ27: MB003544Z / MB003545Z | AK27: 0
A28: BOQ0400DW1050 | B28: BQ | C28: 1 | D28: 1050 | E28: 755 | F28: 0.04 | G28: BOB NBR5906 EP D/O 4,00X1050 | H28: - | L28: ARCELOR | M28: ANCHIETA | N28: Panelinha | O28: B | P28: Jarinu | Q28: Diadema | R28: Diadema | S28: Ferrolene | T28: 15.561312 | U28: 20.24048 | V28: 30.47616 | W28: 23.088 | X28: 20.89464 | Y28: =AVERAGE(T28:X28) -> 22.052118 | Z28: X | AA28: X | AB28: X | AC28: X | AD28: X | AE28: X | AF28: X | AG28: =COUNTIF(Z28:AF28,"X")/7 -> 1 | AH28: =IF(AG28=100%,Y28," ") -> 22.052118 | AI28: 2 | AJ28: MB000412Z / MB000413Z | AK28: 0 | AM28: Em processo de desenvolvimento de nova ferramenta. Realizado comparação de preço de MP para as novas ferramentas.
A29: SLZ0060TD0455 | B29: SLZ | C29: 0.6 | D29: 455 | E29: - | G29: CR240LA-GI40/40U0,6X1000 | H29: 34025661 | L29: SOLUÇÕES USIMINAS | M29: VW-SBC | N29: POLO /NIVUS /VIRTUS | O29: B | P29: Diadema | Q29: Diadema | R29: Diadema | S29: Diadema | T29: 16.000658 | U29: 18.7224 | V29: 22.596 | W29: 20.6592 | X29: 22.2732 | Y29: =AVERAGE(T29:X29) -> 20.050292 | Z29: X | AA29: X | AB29: X | AC29: X | AD29: X | AE29: X | AF29: X | AG29: =COUNTIF(Z29:AF29,"X")/7 -> 1 | AH29: =IF(AG29=100%,Y29," ") -> 20.050292 | AI29: 2 | AJ29: VW000919Z / VW000920Z | AK29: 0
A30: SLQ0300ED0433 | B30: SLQ | C30: 3 | D30: 433 | E30: - | G30: BOB NBR 6656 LNE38 D/O 3,00X1300MM | H30: 34025370 | L30: SOLUÇÕES USIMINAS | M30: VW-SJP | N30: Saveiro | O30: B | P30: Diadema | Q30: Diadema | R30: Diadema | S30: Diadema | T30: 18.74661 | U30: 22.7574 | V30: 16.4628 | W30: 19.368 | X30: 19.8522 | Y30: =AVERAGE(T30:X30) -> 19.437402 | Z30: X | AA30: X | AB30: X | AC30: X | AD30: X | AE30: X | AF30: X | AG30: =COUNTIF(Z30:AF30,"X")/7 -> 1 | AH30: =IF(AG30=100%,Y30," ") -> 19.437402 | AI30: 6 | AJ30: VW000928Z / VW000929Z / VW000917Z / VW000918Z / VW000593Z / VW000594Z | AK30: 0
A31: CHZ0060TD05000500 | B31: CHZ | G31: CR240LA-GI40/40U0,6X1000 | H31: 34028964 | L31: SOLUÇÕES USIMINAS | M31: VW-SBC | N31: POLO /NIVUS /VIRTUS | O31: B | P31: Diadema | Q31: Diadema | R31: Sul | S31: Diadema | T31: 18.010124 | U31: 16.257984 | V31: 21.339776 | W31: 18.56448 | X31: 19.427072 | Y31: =AVERAGE(T31:X31) -> 18.719887 | Z31: X | AA31: X | AB31: X | AC31: X | AD31: X | AE31: X | AF31: X | AG31: =COUNTIF(Z31:AF31,"X")/7 -> 1 | AH31: =IF(AG31=100%,Y31," ") -> 18.719887 | AI31: 2 | AJ31: VW0001048Z / VW0001049Z - DD000502/503Z | AK31: =69601.91/12 -> 5800.1592 | AM31: Em análise de custos | AN31: 46266
A32: BOZ0150HX1250 | B32: BZ | C32: 1.5 | D32: 1250 | E32: - | F32: NÃO | G32: GMW3032M-ST-S-340LA-HD60G60G-U 1,5X1000 | H32: - | L32: USIMINAS | M32: GM/JARINU | N32: TRACKER | O32: B | P32: Diadema | Q32: Diadema | R32: Diadema | S32: Diadema | T32: 8.118495 | U32: 17.01018 | V32: 28.221435 | W32: 18.169965 | X32: 20.87613 | Y32: =AVERAGE(T32:X32) -> 18.479241 | Z32: X | AA32: X | AB32: X | AC32: X | AD32: X | AE32: X | AF32: X | AG32: =COUNTIF(Z32:AF32,"X")/7 -> 1 | AH32: =IF(AG32=100%,Y32," ") -> 18.479241 | AI32: 2 | AJ32: GM000408Z / GM000409Z | AK32: 11042.36 | AM32: REDUZIR PASSO DE 210 mm PARA 195 mm. REDUÇÃO DE PESO BRUTO DE 1,561 KG PARA 1,464 KG. | AN32: 46113 | AO32: Sim
A33: BOZ0140HX1100 | B33: BZ | C33: 1.4 | D33: 1100 | E33: - | G33: BOB1,40X1000 GMW3032M-ST-S-CR340LA-HD60G | H33: - | L33: USIMINAS | M33: GM/JARINU | N33: JOY/JOY PLUS | O33: B | P33: Sul | Q33: Sul | R33: Diadema | S33: Diadema | T33: 8.56086 | U33: 17.6253 | V33: 27.6969 | W33: 18.12888 | X33: 19.13604 | Y33: =AVERAGE(T33:X33) -> 18.229596 | Z33: X | AA33: X | AB33: X | AC33: X | AD33: X | AE33: X | AF33: X | AG33: =COUNTIF(Z33:AF33,"X")/7 -> 1 | AH33: =IF(AG33=100%,Y33," ") -> 18.229596 | AI33: 2 | AJ33: GM000402Z / 403Z | AK33: 4861.65 | AM33: Redução de 15mm no passo do blank (183g/blank) | AN33: 46143 | AO33: Sim
A34: BOQ0600IH1000 | B34: BQ | C34: 6 | D34: 1100 | E34: - | G34: BOB 6656 LNE38 6,0(-0,00/+0,30 MTH)X1000 | H34: - | L34: USIMINAS | M34: ANCHIETA / MBB | N34: MBB Travessas 72 | O34: B | P34: Diadema | Q34: Diadema | R34: Diadema | S34: Ferrolene | T34: 15.53772 | U34: 15.34104 | V34: 19.47132 | W34: 18.88128 | X34: 18.88128 | Y34: =AVERAGE(T34:X34) -> 17.622528 | Z34: X | AA34: X | AB34: X | AC34: X | AD34: X | AE34: X | AF34: X | AG34: =COUNTIF(Z34:AF34,"X")/7 -> 1 | AH34: =IF(AG34=100%,Y34," ") -> 17.622528 | AI34: 2 | AJ34: VW000166AA / MB000072Z | AK34: 0
A35: SLF0200TH0400 | B35: SLF | C35: 1.75 | D35: 300 | E35: 164 | F35: 0.075 | G35: BOB VW 50065 CR380LA UC-U-O 2,00X1200MM | H35: 34025662 | L35: SOLUÇÕES USIMINAS | M35: JARINU | N35: Nivus | O35: B | P35: Diadema | Q35: Diadema | R35: Diadema | S35: Diadema | T35: 14.9532 | U35: 17.592 | V35: 17.94384 | W35: 17.94384 | X35: 16.53648 | Y35: =AVERAGE(T35:X35) -> 16.993872 | Z35: X | AA35: X | AB35: X | AC35: X | AD35: X | AE35: X | AF35: X | AG35: =COUNTIF(Z35:AF35,"X")/7 -> 1 | AH35: =IF(AG35=100%,Y35," ") -> 16.993872 | AI35: 2 | AJ35: DJ000079Z / 080Z | AK35: 14192.72 | AM35: Redução da largura do slitter de 400mm para 366mm | AN35: 46235 | AO35: Sim
A36: BOF0090UQ1100 | B36: BF | C36: 0.7 | D36: 300 | E36: 150 | F36: 0.045 | G36: GMW3399M-ST-S-CR980T/700Y-MP-LCE-UNC | H36: - | L36: USIMINAS | M36: GM/JARINU | N36: TRACKER | O36: B | P36: Diadema | Q36: Diadema | R36: Diadema | S36: Diadema | T36: 12.315858 | U36: 14.371656 | V36: 24.588808 | W36: 13.912288 | X36: 15.618512 | Y36: =AVERAGE(T36:X36) -> 16.161424 | AG36: =COUNTIF(Z36:AF36,"X")/7 -> 0 | AH36: =IF(AG36=100%,Y36," ") | AI36: 3 | AJ36: DJ000057Z / DJ000058Z / DJ000228Z | AK36: 0
A37: BOF0060HZ1050 | B37: BF | G37: GMW2M-ST-S-CR2-UNCOATED-U 0,60X1100 | H37: - | L37: USIMINAS | M37: GM | N37: TRACKER | O37: B | P37: Diadema | Q37: Diadema | R37: Diadema | S37: Diadema | T37: 12.4568 | U37: 15.7064 | V37: 18.4144 | W37: 15.1648 | X37: 15.7064 | Y37: =AVERAGE(T37:X37) -> 15.48976 | AG37: =COUNTIF(Z37:AF37,"X")/7 -> 0 | AH37: =IF(AG37=100%,Y37," ") | AI37: 4 | AJ37: GM000432Z / GM000433Z / GM000446Z / GM000447Z | AK37: 0
A38: BOQ0600DW1050 | B38: BQ | G38: BOB NBR6656 LNE280 6,00X1050MM | H38: - | L38: USIMINAS | M38: MERCEDES | N38: Console | O38: B | P38: Diadema | Q38: Diadema | R38: Diadema | S38: Ferrolene | T38: 11.44408 | U38: 12.0464 | V38: 14.68155 | W38: 14.68155 | X38: 18.604159 | Y38: =AVERAGE(T38:X38) -> 14.291548 | Z38: X | AA38: X | AB38: X | AC38: X | AD38: X | AE38: X | AF38: X | AG38: =COUNTIF(Z38:AF38,"X")/7 -> 1 | AH38: =IF(AG38=100%,Y38," ") -> 14.291548 | AI38: 4 | AJ38: DA000198Z / DA000199Z / DA000200Z / DA000229Z | AK38: 0
A39: BOQ0475EE1230 | B39: BQ | C39: 4.75 | D39: 1230 | E39: - | G39: CH NBR6656 LNE50 D/O | H39: - | J39: 69 | K39: 23 | L39: ARCELOR | M39: ANCHIETA | N39: MBB | O39: B | P39: Diadema | Q39: Diadema | R39: Diadema | S39: Ferrolene | T39: 12.8765 | U39: 12.38236 | V39: 16.1069 | W39: 13.1872 | X39: 15.9889 | Y39: =AVERAGE(T39:X39) -> 14.108372 | Z39: X | AA39: X | AB39: X | AC39: X | AD39: X | AE39: X | AF39: X | AG39: =COUNTIF(Z39:AF39,"X")/7 -> 1 | AH39: =IF(AG39=100%,Y39," ") -> 14.108372 | AI39: 13 | AJ39: VB000346LA / DA000480Z / MB003597LA / MB003598LA / MB003594LA / MB003595LA / MB003607LA / MB003608LA / MB002301LA / MB003563Z / MB003564Z / MB003540Z / MB003541Z | AK39: 2486.5 | AM39: Redução do peso bruto das peças cortadas na máquina laser (Aumento de peças / chapa) | AN39: 46113 | AO39: Sim
A40: BOQ0300BF1450 | B40: BQ | C40: 3 | D40: 1450 | E40: - | G40: BOB EN10149-2 S355MC 3,00X1500 MTL D/O | H40: - | L40: USIMINAS | M40: ANCHIETA / SCANIA | N40: Mundguard / Front Module /New Mundguard | O40: B | P40: Diadema | Q40: Diadema | R40: Diadema | S40: Ferrolene | T40: 5.50615 | U40: 14.867388 | V40: 18.702372 | W40: 14.355246 | X40: 16.549896 | Y40: =AVERAGE(T40:X40) -> 13.99621 | AG40: =COUNTIF(Z40:AF40,"X")/7 -> 0 | AH40: =IF(AG40=100%,Y40," ") | AI40: 5 | AJ40: DA000450AA / DA000451AA / DA000526LC / 526LF / 526LG | AK40: 0
A41: BOZ0120IC1100 | B41: BZ | C41: 1.2 | D41: 1100 | E41: - | G41: GMW3032M-STS-CR420LAHD60G60-GU | H41: - | L41: USIMINAS | M41: GM | N41: SPIN | O41: B | P41: Diadema | Q41: Diadema | R41: Diadema | S41: Diadema | T41: 10.476078 | U41: 11.337382 | V41: 17.497578 | W41: 14.41748 | X41: 15.363042 | Y41: =AVERAGE(T41:X41) -> 13.818312 | AG41: =COUNTIF(Z41:AF41,"X")/7 -> 0 | AH41: =IF(AG41=100%,Y41," ") | AI41: 8 | AJ41: GM000065AY / GM000066AY / GM000218Z / GM000219Z / GM000359AA / GM000364Z / GM000463Z / VW000154AB | AK41: 0
...

Sheet A.Propostas
AM1: SIM
B2: BSW - PROPOSTAS PARA REDUÇÕES | Y2: STATUS | AM2: NÃO
AM3: EM IMPLEMENTAÇÃO
B4: DADOS DO MATERIAL (USAR PLANILHA DE DEMANDA ENVIADA) | J4: ESPESSURA | N4: BORDAS APARADAS | Q4: ALTERAÇÕES DE QUALIDADE | T4: ALTERAÇÃO DE MEDIDA | Y4: SOLICITANTE | Z4: COMPRAS | AA4: COMPRAS | AB4: COMPRAS | AC4: COMPRAS | AD4: COMPRAS | AE4: ENGENHARIA | AF4: COMPRAS | AG4: COMPRAS | AH4: COMPRAS | AI4: LOGÍSTICA | AJ4: COMPRAS | AK4: TODOS | AM4: KAIZEN PLANO DE CORTE
A5: Nome do Projeto | B5: CÓDIGO DELGA | C5: Qual projeto esse item faz parte? | D5: DESCRIÇÃO | E5: MÉDIA CONSUMO FEV ~ MAI | F5: REDUÇÃO POTENCIAL (R$ ANUAL) | G5: PLANTA DELGA | H5: FONTE | J5: ESP. NOMINAL (mm) | K5: TOLERANCIA ESP. ATUAL (mm) | L5: TOLERANCIA ESP. PROPOSTA DELGA (mm) | N5: TOLERANCIA ATUAL (mm) | O5: TOLERANCIA PROPOSTA DELGA (mm) | Q5: QUALIDADE ATUAL | R5: QUALIDADE PROPOSTA | T5: LARGURA ATUAL | U5: LARGURA PROPOSTA | V5: COMPRIMENTO ATUAL | W5: COMPRIMENTO PROPOSTO | Y5: FORMALIZADO COM COMPRAS | Z5: PASSADO PARA USINA ? | AA5: DATA ENVIO P/ USINA | AB5: PRAZO DA USINA PARA RETORNO | AC5: DATA DE DEVOLUÇÃO DA CONSULTA | AD5: VIABILIDADE TÉCNICA | AE5: ENVIO DE PLANO DE CORTE PARA COMPRAS | AF5: ENVIO DO PLANO DE CORTE PARA USINAS | AG5: PRAZO PARA CADASTRO DO NOVO PN (LIBERAR PROGRAMAÇÃO) | AH5: DATA DE CADASTRO DO NOVO PN (Usina) | AI5: PRAZO DE RECEBIMENTO NAS NOVAS ESPECIFICAÇÕES (APROXIMADO) | AJ5: ÁREA PENDENTE DE ATUAÇÃO PARA EVOLUÇÃO DO PROJETO | AK5: HISTÓRICO
B6: BOQ1225BA1250 | D6: BOQ B105-13 12,25-0,00/+0,58X1250 MTH | E6: 289 | F6: 150216.36 | G6: FERRAZ | H6: USIMINAS | J6: 12.25 | K6: -0,00 / +0,58 | L6: 12,50 (-0,25/+0,23) | N6: -0,00 / +38,00 | O6: -0,00 / +30,00 | Q6: B105-13 | R6: N/A | T6: 1250 | U6: N/A | V6: N/A | W6: N/A | Y6: Data não informada. | Z6: SIM | AA6: 46280 | AB6: 46302 | AC6: 46295 | AD6: VIÁVEL COM RESTRIÇÕES | AE6: N/A | AF6: N/A | AG6: 46303 | AH6: 46303 | AJ6: USINA - CADASTRO DE NOVO PART NUMBER | AK6: ALTERAÇÃO DE PART NUMBER (ESP.) CONSULTA REVISADA 2601342 TOLERANCIA ESP. 04/08 - ENVIADO NOVA PROPOSTA PARA USIMINAS
B7: BOQ1575BA1250 | D7: BOQ B105-13 15,75-0,00/+0,58X1250 MTH | E7: 283.69 | F7: 102925.44 | G7: FERRAZ | H7: USIMINAS | J7: 15.75 | K7: -0,00 / +0,58 | L7: -0,00 / +0,58 | N7: -0,00 / +38,00 | O7: -0,00 / +25,00 | Q7: B105-13 | R7: N/A | T7: 1250 | U7: N/A | V7: N/A | W7: N/A | Y7: Data não informada. | Z7: SIM | AA7: 46238 | AB7: 46259 | AC7: 46280 | AD7: VIÁVEL COM RESTRIÇÕES | AE7: N/A | AF7: N/A | AG7: 46280 | AH7: 46280 | AJ7: LOGÍSTICA - PROGRAMAÇÃO | AK7: MTL INVIÁVEL, GANHAMOS NA ALTERAÇÃO DE BORDAS
B8: BOQ1175AY1050 | D8: BOQ USISAR55 11,75+0,54X1050 MTH | E8: 188.3 | F8: 190474.65 | G8: FERRAZ | H8: USIMINAS | J8: 11.75 | K8: -0,00 / +0,54 | L8: -0,25 / +0,05 | N8: -0,00 / +32,00 | O8: -0,00 / +25,00 | Q8: USISAR55 | R8: N/A | T8: 1050 | U8: N/A | V8: N/A | W8: N/A | Y8: Data não informada. | Z8: SIM | AA8: 45722 | AB8: 46118 | AC8: 46140 | AD8: VIÁVEL | AE8: N/A | AF8: N/A | AG8: 46262 | AH8: 46267 | AI8: AGUARDANDO PROGRAMAÇÃO | AJ8: LOGÍSTICA - PROGRAMAÇÃO | AK8: ALTERAÇÃO DE PART NUMBER (ESP.)
A9: 06 - Redução consumo MTP aplicando tolerância mínima | B9: SLZ0180SI0366 | C9: Mean to-low Curva A | D9: SLZ VW50065 CR300LA-GI40/40U 1,80X366 | E9: 87.74 | F9: 168140.89 | G9: JARINU | H9: S.U | J9: =MID(B9,4,4)/100 -> 1.8 | K9: +/-0,07 | L9: -0,04 / +0,00 +0,03 / -0,07 PROPOSTA USINA | N9: N/A | O9: N/A | Q9: N/A | R9: N/A | T9: N/A | U9: N/A | V9: N/A | W9: N/A | Y9: Data não informada. | Z9: SIM | AA9: 46093 | AB9: 46108 | AC9: 46155 | AD9: VIÁVEL | AE9: 46231 | AF9: 46248 | AG9: 46174 | AH9: 46174 | AI9: 46285 | AJ9: USINA - EM PRODUÇÃO | AK9: ITEM ENVIADO NO PRIMEIRO PACOTE DE SOLICITAÇÕES DE MODIFICAÇÕES
A10: 06 - Redução consumo MTP aplicando tolerância mínima | B10: BDZ0140SI03120950 | C10: Mean to-low Curva A | D10: VW50065 CR300LA GI40/40U 1,40X312,5X950 | E10: 33.04 | F10: =76639.7953125005+90849.43 -> 167489.23 | G10: JARINU | H10: GONVARRI | J10: =MID(B10,4,4)/100 -> 1.4 | K10: +/-0,075 | L10: -0,0375 / +0,00 | N10: N/A | O10: N/A | Q10: N/A | R10: N/A | T10: 950 | U10: N/A | V10: 312 | W10: 302 | Y10: Data não informada. | Z10: SIM | AA10: 46269 | AB10: INVIÁVEL | AC10: INVIÁVEL | AD10: INVIÁVEL | AE10: INVIÁVEL | AF10: INVIÁVEL | AG10: INVIÁVEL | AH10: INVIÁVEL | AI10: INVIÁVEL | AJ10: INVIÁVEL | AK10: FORNECEDOR IRÁ COMUNICAR A VW AS ALTERAÇÕES
B11: BOQ0800IS1200 | D11: NBRLNE500 | E11: 78.8 | F11: 223577.79 | G11: FERRAZ | H11: ARCELOR | J11: 8 | K11: -0,00 / +0,58 | L11: -0,25 / +0,05 | N11: N/A | O11: N/A | Q11: N/A | R11: N/A | T11: 1200 | U11: 1450 1250 | V11: 1750 / 3000 | W11: 2620 / 2700 / 2960 2450 / 2700 / 2950 | Y11: Data não informada. | Z11: SIM | AA11: N/A | AB11: N/A | AC11: N/A | AD11: VIÁVEL | AE11: N/A | AF11: N/A | AG11: N/A | AH11: 46153 | AI11: 46254 | AJ11: LOGÍSTICA - PROGRAMAÇÃO | AK11: MATERIAL COM 1450MM JÁ CHEGOU. MATERIAL COM 1200MM PENDENTE
B12: BOQ1000AY1050 | D12: USISAR55 | E12: 76.4 | F12: 21403.13 | G12: FERRAZ | H12: USIMINAS | J12: 10 | K12: -0,25 / +0,05 | L12: -0,25 / +0,05 | N12: -0,00 / +32,00 | O12: -0,00 / +25,00 | Q12: N/A | R12: N/A | T12: 1050 | U12: N/A | V12: N/A | W12: N/A | Y12: 46130 | Z12: SIM | AA12: 46136 | AB12: 46166 | AC12: 46227 | AD12: VIÁVEL COM RESTRIÇÕES | AE12: N/A | AF12: N/A | AG12: 46283 | AH12: 46289 | AJ12: LOGÍSTICA - PROGRAMAÇÃO | AK12: CONSULTA DEVOVLIDA 24/07/2026 - VIÁVEL APENAS RESTRIÇÃO NA LARGURA
B13: BOQ1275BA1250 | D13: BOQ B105-13 12,75X1250 MTH | E13: 67.69 | F13: 7443.6 | G13: FERRAZ | H13: USIMINAS | J13: 12.75 | K13: -0,00 / +0,58 | L13: -0,25 / +0,05 | N13: -0,00 / +38,00 | O13: -0,00 / +25,00 | Q13: B105-13 | R13: N/A | T13: 1250 | U13: N/A | V13: N/A | W13: N/A | Y13: 46094 | Z13: SIM | AA13: 46136 | AB13: 46297 | AD13: RECONSULTA | AE13: N/A | AF13: N/A | AJ13: USINA - CONSULTA | AK13: RECONSULTA ABERTA PARA RESTRIÇÃO APENAS DE LARGURA
A14: 06 - Redução consumo MTP aplicando tolerância mínima | B14: SLZ0180SI0325 | C14: Mean to-low Curva A | D14: SLZ VW50065 CR300LA GI40/40U 1,80X325 | E14: 59.67 | F14: 113701.83 | G14: JARINU | H14: S.U | J14: =MID(B14,4,4)/100 -> 1.8 | K14: +/-0,08 | L14: -0,04 / +0,00 +0,03 / -0,07 PROPOSTA USINA | N14: N/A | O14: N/A | Q14: N/A | R14: N/A | T14: N/A | U14: N/A | V14: N/A | W14: N/A | Y14: Data não informada. | Z14: SIM | AA14: 46093 | AB14: 46108 | AC14: 46155 | AD14: VIÁVEL | AE14: 46231 | AF14: 46248 | AG14: 46174 | AH14: 46174 | AI14: 46285 | AJ14: USINA - EM PRODUÇÃO | AK14: ITEM ENVIADO NO PRIMEIRO PACOTE DE SOLICITAÇÕES DE MODIFICAÇÕES
A15: 06 - Redução consumo MTP aplicando tolerância mínima | B15: BDZ0140SI05750517 | C15: Mean to-low Curva A | D15: BDZ VW50065 CR300LA GI40/40 1,40X575X517 | E15: 36.52 | F15: =66510.6497055+47086.87 -> 113597.52 | G15: JARINU | H15: CSN | J15: =MID(B15,4,4)/100 -> 1.4 | K15: +/-0,065 | L15: -0,0325 / +0 | N15: N/A | O15: N/A | Q15: N/A | R15: N/A | T15: 517 | U15: N/A | V15: 575 | W15: 565 | Y15: Data não informada. | Z15: NÃO | AA15: INVIÁVEL | AB15: INVIÁVEL | AC15: INVIÁVEL | AD15: INVIÁVEL | AE15: INVIÁVEL | AF15: INVIÁVEL | AG15: INVIÁVEL | AH15: INVIÁVEL | AI15: INVIÁVEL | AJ15: INVIÁVEL | AK15: INVIABILIDADE - FORNECEDOR DIRECT BUY IRÁ COMUNICAR A VW
A16: 06 - Redução consumo MTP aplicando tolerância mínima | B16: SLZ0180SI0466 | C16: Mean to-low Curva A | D16: SLZ VW50065 CR300LA-GI40/40U 1,80X466 | E16: 25.64 | F16: =47874.1634078397+63041.48 -> 110915.64 | G16: JARINU | H16: S.U | J16: =MID(B16,4,4)/100 -> 1.8 | K16: +/-0,08 | L16: -0,04 / +0,00 PROPOSTA DELGA +0,02 / -0,08 PROPOSTA USINA | N16: N/A | O16: N/A | Q16: N/A | R16: N/A | T16: 466 | U16: 451 | V16: 185 | W16: 185 | Y16: Data não informada. | Z16: SIM | AA16: 46093 | AB16: 46118 | AC16: 46155 | AD16: VIÁVEL | AE16: PENDENTE | AF16: PENDENTE | AJ16: USINA - RECEBIMENTO ENGENHARIA - REGULARIZAR PLANO DE CORTE | AK16: ITEM ENVIADO NO PRIMEIRO PACOTE DE SOLICITAÇÕES DE MODIFICAÇÕES 20/07/2026 - APROVADO ALTERAÇÕES DE LARGURA S/ ALTERAÇÕES DE PREÇO. NECESSÁRIO ENVIO DO PLANO DE CORTE PLANO DE CORTE FALTA ALTERAR CÓDIGO DE LARGURA
B17: BOQ0975AB1250 | D17: SAE1008 | E17: 52.22 | F17: 117470.3 | G17: FERRAZ | H17: ARCELOR | J17: 9.75 | K17: -0,00 / +0,56 | L17: -0,25 / +0,05 | N17: -0,00 / +30,00 | O17: -0,00 / +0,25 | Q17: N/A | R17: N/A | T17: N/A | U17: N/A | V17: N/A | W17: N/A | Y17: Data não informada. | Z17: SIM | AA17: 46162 | AB17: 46193 | AC17: 46181 | AD17: VIÁVEL | AE17: PENDENTE | AF17: N/A | AG17: 46240 | AH17: 46240 | AI17: 46357 | AJ17: USINA - EM PRODUÇÃO | AK17: MATERIAL PROGRAMADO
B18: BOQ0580TV1500 | D18: S700MC | E18: 45.75 | F18: 0 | G18: FERRAZ | H18: ARCELOR | J18: 5.8 | K18: N/A | L18: N/A | N18: N/A | O18: N/A | Q18: N/A | R18: N/A | T18: 1500 | U18: N/A | V18: 2630 1930 | W18: 6510 2960 | Y18: Data não informada. | Z18: N/A | AA18: N/A | AB18: N/A | AC18: N/A | AD18: VIÁVEL | AE18: N/A | AF18: N/A | AG18: N/A | AH18: N/A | AI18: N/A | AJ18: LOGÍSTICA - PROGRAMAÇÃO | AK18: CONFIRMAR RECEBIMENTO NAS NOVAS ESPECIFICAÇÕES
B19: BOQ0680TV1500 | D19: S700MC | E19: 44.43 | G19: FERRAZ | H19: FERROLENE | J19: 6.8 | K19: -0,10 / +0,40 | L19: N/A | N19: -0,00 / +38,00 | O19: N/A | Q19: N/A | R19: N/A | T19: 1500 | U19: N/A | V19: CHQ0680TV15002680 | W19: CHQ0680TV15002640 CHQ0680TV15002650 | Y19: Data não informada. | Z19: N/A | AA19: N/A | AB19: N/A | AC19: N/A | AD19: VIÁVEL | AE19: N/A | AF19: N/A | AG19: N/A | AH19: N/A | AJ19: LOGÍSTICA - PROGRAMAÇÃO | AK19: CONFIRMAR RECEBIMENTO NAS NOVAS ESPECIFICAÇÕES
B20: BOQ0680TV1500 | D20: S700MC | E20: 44.43 | G20: FERRAZ | H20: USIMINAS | J20: 6.8 | K20: -0,10 / +0,40 | L20: 7,00 -0,25 / +0,05 | N20: -0,00 / +38,00 | O20: -0,00 / +25,00 | Q20: N/A | R20: N/A | T20: 1500 | U20: N/A | V20: N/A | W20: N/A | Y20: Data não informada. | Z20: SIM | AA20: 46192 | AB20: 46232 | AC20: 46240 | AD20: VIÁVEL COM RESTRIÇÕES | AJ20: ENGENHARIA - REANALISE DE PROPOSTA | AK20: PRIMEIRA CONSULTA METALÚRGICA MOSTROU INVIABILIDADE. LAMINAÇÃO DE UM NOVO ESBOÇO ACONTECENDO NA KW31, REAVALIAÇÃO DA CONSULTA PROPOSTA APRESENTADA 06/08 COM RESTRIÇÃO A SER AVALIADA PELA ENGENHARIA
B21: BOF0100TR1350 | C21: Largura de bobina | D21: PAINEL LATERAL INTERNO VW 50065 CR440Y780T-DPSUP - ESQ /DIR | E21: 171.51 | F21: 96985.81 | G21: JARINU | H21: S.U | J21: N/A | N21: N/A | O21: N/A | Q21: N/A | R21: N/A | T21: 1350 | U21: 1345 | V21: 315 | W21: N/A | Y21: Data não informada. | Z21: SIM | AA21: 46093 | AB21: 46237 | AC21: 46223 | AD21: VIÁVEL COM RESTRIÇÕES | AE21: PENDENTE | AF21: PENDENTE | AI21: 46285 | AJ21: USINA - RECEBIMENTO ENGENHARIA - REGULARIZAR PLANO DE CORTE | AK21: 20/07/2026 - APROVADO ALTERAÇÕES DE LARGURA S/ ALTERAÇÕES DE PREÇO. NECESSÁRIO ENVIO DO PLANO DE CORTE | AL21: nok
B22: SLZ0120UI1250 | C22: largura aprovado | D22: BOZ VW50065 CR3-GI40/40-U-O 1,20X1250 | E22: 34.83 | F22: =13191.83+78959.6057250004 -> 92151.436 | G22: JARINU | H22: S.U | J22: 1.2 | K22: +/-0,055 | L22: -0,0275 / +0,00 - PROPOSTA DELGA +0,00 / -0,06 PROPOSTA USINA +0,00 / -0,04 CONTRAPOPOSTA DECLINADA | N22: -0,00 / +12 | O22: -0,00 / +6,0 | Q22: N/A | R22: N/A | T22: N/A | U22: N/A | V22: N/A | W22: N/A | Y22: Data não informada. | Z22: N/A | AA22: INVIÁVEL | AB22: INVIÁVEL | AC22: INVIÁVEL | AD22: INVIÁVEL | AE22: INVIÁVEL | AF22: INVIÁVEL | AG22: INVIÁVEL | AH22: INVIÁVEL | AI22: INVIÁVEL | AJ22: INVIÁVEL | AK22: CONTRATPOPOSTA DELGA PARA TOLERANCIA PROPOSTA PELA USINA NOVA TOLERANCIA SOLICITADA INVIÁVEL
A23: 06 - Redução consumo MTP aplicando tolerância mínima | B23: SLZ0070SH0275 | C23: Mean to-low Curva A | D23: SLZ VW50065 CR300LA-GI40/40 0,70X275 | E23: 24.12 | F23: 80839.728 | G23: JARINU | H23: S.U | J23: =MID(B23,4,4)/100 -> 0.7 | K23: +/-0,04 | L23: -0,02 / +0,00 PROPOSTA DELGA +0,00 / -0,06 PROPOSTA USINA +0,00 / -0,04 CONTRAPOPOSTA DECLINADA | N23: N/A | O23: N/A | Q23: N/A | R23: N/A | T23: N/A | U23: N/A | V23: N/A | W23: N/A | Y23: Data não informada. | Z23: N/A | AA23: INVIÁVEL | AB23: INVIÁVEL | AC23: INVIÁVEL | AD23: INVIÁVEL | AE23: INVIÁVEL | AF23: INVIÁVEL | AG23: INVIÁVEL | AH23: INVIÁVEL | AI23: INVIÁVEL | AJ23: INVIÁVEL | AK23: CONTRATPOPOSTA DELGA PARA TOLERANCIA PROPOSTA PELA USINA NOVA TOLERANCIA SOLICITADA INVIÁVEL
A24: 06 - Redução consumo MTP aplicando tolerância mínima | B24: SLZ0150SI0725 | C24: Mean to-low Curva A | D24: SLZ VW50065 CR300LA-GI40/40U 1,50X725 | E24: 58.78 | F24: 77871.276 | G24: JARINU | H24: S.U | J24: =MID(B24,4,4)/100 -> 1.5 | K24: +/-0,07 | L24: -0,0375 / 0 - PROPOSTA DELGA +0,03 / -0,07 - PROPOSTA USINA | N24: N/A | O24: N/A | Q24: N/A | R24: N/A | T24: N/A | U24: N/A | V24: N/A | W24: N/A | Y24: Data não informada. | Z24: SIM | AA24: 46093 | AB24: 46108 | AC24: 46155 | AD24: VIÁVEL | AE24: 46231 | AF24: 46248 | AG24: 46174 | AH24: 46174 | AI24: 46285 | AJ24: USINA - EM PRODUÇÃO | AK24: ITEM ENVIADO NO PRIMEIRO PACOTE DE SOLICITAÇÕES DE MODIFICAÇÕES
A25: 06 - Redução consumo MTP aplicando tolerância mínima | B25: BOZ0120UI0950 | C25: Mean to-low Curva A | D25: BOB VW50065 CR3 GI40/40 1,20X0950MM | E25: 21.47 | F25: =10393.72+31672.6645679009+34645.74 -> 76712.125 | G25: JARINU | H25: S.U | J25: =MID(B25,4,4)/100 -> 1.2 | K25: +/-0,04 | L25: +0,00 / -0,04 - PROPOSTA USINA | N25: -0,00 / +12 | O25: -0,00 / +6,0 | Q25: N/A | R25: N/A | T25: 950 | U25: 930 | V25: 378 | W25: 378 | Y25: Data não informada. | Z25: SIM | AA25: 46184 | AB25: 46237 | AC25: 46223 | AD25: VIÁVEL COM RESTRIÇÕES | AE25: PENDENTE | AF25: PENDENTE | AJ25: USINA - RECEBIMENTO ENGENHARIA - REGULARIZAR PLANO DE CORTE | AK25: CONTRATPOPOSTA DELGA PARA TOLERANCIA PROPOSTA PELA USINA 20/07/2026 - APROVADO ALTERAÇÕES DE LARGURA S/ ALTERAÇÕES DE PREÇO. NECESSÁRIO ENVIO DO PLANO DE CORTE NOVA TOLERANCIA SOLICITADA INVIÁVEL | AL25: nok
A26: 06 - Redução consumo MTP aplicando tolerância mínima | B26: SLZ0070QH0650 | C26: Mean to-low Curva A | D26: SLZ VW50065 CR4 GI40/40-U 0,70X650 | E26: 19.17 | F26: 43204.422 | G26: JARINU | H26: S.U | J26: =MID(B26,4,4)/100 -> 0.7 | K26: +/-0,04 | L26: -0,02 / +0,00 PROPOSTA DELGA +0,00 / -0,06 PROPOSTA USINA +0,00 / -0,04 CONTRAPOPOSTA DECLINADA | N26: N/A | O26: N/A | Q26: N/A | R26: N/A | T26: N/A | U26: N/A | V26: N/A | W26: N/A | Y26: Data não informada. | Z26: N/A | AA26: INVIÁVEL | AB26: INVIÁVEL | AC26: INVIÁVEL | AD26: INVIÁVEL | AE26: INVIÁVEL | AF26: INVIÁVEL | AG26: INVIÁVEL | AH26: INVIÁVEL | AI26: INVIÁVEL | AJ26: INVIÁVEL | AK26: CONTRATPOPOSTA DELGA PARA TOLERANCIA PROPOSTA PELA USINA NOVA TOLERANCIA SOLICITADA INVIÁVEL
A27: 06 - Redução consumo MTP aplicando tolerância mínima | B27: BOZ0120QH0900 | C27: Mean to-low Curva A | D27: BOZ VW50065 CR4-GI40/40 1,20X900 | E27: 21.47 | F27: =11347.81+31670.2095128998 -> 43018.02 | G27: JARINU | H27: S.U | J27: =MID(B27,4,4)/100 -> 1.2 | K27: +/-0,04 | L27: +0,00 / -0,04 - PROPOSTA USINA | N27: -0,00 / +12 | O27: -0,00 / +6,0 | Q27: N/A | R27: N/A | T27: N/A | U27: N/A | V27: N/A | W27: N/A | Y27: Data não informada. | Z27: SIM | AA27: 46093 | AB27: 46108 | AC27: 46155 | AD27: VIÁVEL | AE27: 46231 | AF27: 46248 | AG27: 46174 | AH27: 46174 | AI27: 46285 | AJ27: USINA - EM PRODUÇÃO | AK27: ITEM ENVIADO NO PRIMEIRO PACOTE DE SOLICITAÇÕES DE MODIFICAÇÕES
A28: 27 - Redução consumo MTP aplicando tolerância mínima curva B | B28: SLZ0065TD0750 | C28: Mean to-low Curva B | D28: VW50065-CR240LA-GI40/40 | E28: 16.02832 | F28: 42227.411 | G28: JARINU | H28: S.U | J28: 0.65 | K28: ±0,04 | L28: -0,02 / +0,00 PROPOSTA DELGA INVIÁVEL MTL | N28: N/A | O28: N/A | Q28: N/A | R28: N/A | T28: N/A | U28: N/A | V28: N/A | W28: N/A | Y28: Data não informada. | Z28: SIM | AA28: INVIÁVEL | AB28: INVIÁVEL | AC28: INVIÁVEL | AD28: INVIÁVEL | AE28: INVIÁVEL | AF28: INVIÁVEL | AG28: INVIÁVEL | AH28: INVIÁVEL | AI28: INVIÁVEL | AJ28: INVIÁVEL | AK28: INVIÁVEL
B29: BOZ0070TD1500 | C29: Bordas aparadas | D29: VW50065-CR240LA-GI40/40 | E29: 35.13 | F29: 35917.45 | G29: JARINU | H29: S.U | J29: N/A | K29: N/A | L29: N/A | N29: -0,00 / + 12,00 | O29: -0,00 / +6,0 | Q29: N/A | R29: N/A | T29: N/A | U29: N/A | V29: N/A | W29: N/A | Y29: Data não informada. | Z29: NÃO | AJ29: COMPRAS - ENVIO PARA USINA
A30: 45 - Redução de MP GM000409Z. 49 - REDUÇÃO DE MP GM000408Z / GM000409Z | B30: BOZ0150HX1250 | D30: GMW3032M-STS CR340LA-HD60G60G-1,50X1250 | E30: 22.5 | F30: 99381.26 | G30: DIADEMA | H30: USIMINAS | J30: 1.5 | K30: N/A | L30: N/A | N30: N/A | O30: N/A | Q30: N/A | R30: N/A | T30: 1250 | U30: 1200 | V30: 210 | W30: 195 | Y30: Data não informada. | Z30: SIM | AA30: 46120 | AB30: 46141 | AC30: 46134 | AD30: VIÁVEL | AE30: N/A | AF30: N/A | AG30: VERIFICAR PROGRAMAÇÃO | AH30: 46247 | AI30: VERIFICAR PROGRAMAÇÃO | AJ30: LOGÍSTICA - PROGRAMAÇÃO | AK30: ENVIADO CONFIRMAÇÃO PARA ENG.
A31: 06 - Redução consumo MTP aplicando tolerância mínima | B31: SLZ0175SH0300 | C31: Mean to-low Curva A | D31: SLZ VW50065 CR300LA-GI40/40 1,75X300 | E31: 36.06 | F31: 28224.958 | G31: JARINU | H31: S.U | J31: =MID(B31,4,4)/100 -> 1.75 | K31: +/-0,07 | L31: -0,0375 / +0,00 PROPOSTA DELGA +0,00 / -0,10 PROPOSTA USINA +0,02 / -0,08 PROPOSTA USINA | N31: N/A | O31: N/A | Q31: N/A | R31: N/A | T31: N/A | U31: N/A | V31: N/A | W31: N/A | Y31: Data não informada. | Z31: SIM | AA31: 46184 | AB31: 46214 | AC31: 46227 | AD31: VIÁVEL | AE31: 46231 | AF31: 46248 | AG31: 46235 | AH31: 46235 | AI31: 46346 | AJ31: USINA - EM PRODUÇÃO | AK31: CONTRATPOPOSTA DELGA PARA TOLERANCIA PROPOSTA PELA USINA RECEBIDO OK PARA TOLERANCIA DE +0,03 / -0,07
A32: 27 - Redução consumo MTP aplicando tolerância mínima curva B | B32: BOF0100HE1150 | C32: Mean to-low Curva B | D32: DIN EN 10268 - HC300LA | E32: 14.416588 | F32: 34245.48 | G32: JARINU | H32: FERROLENE | J32: 1 | K32: ±0,07 | L32: -0,0375 / +0,00 | N32: N/A | O32: N/A | Q32: N/A | R32: N/A | T32: N/A | U32: N/A | V32: N/A | W32: N/A | Y32: Data não informada. | Z32: NÃO | AA32: INVIÁVEL | AB32: INVIÁVEL | AC32: INVIÁVEL | AD32: INVIÁVEL | AE32: INVIÁVEL | AF32: INVIÁVEL | AG32: INVIÁVEL | AH32: INVIÁVEL | AI32: INVIÁVEL | AJ32: INVIÁVEL | AK32: INVIÁVEL - FORNECEDOR IRÁ COMUNICAR VW
A33: 44 - Mudança de fonte Usiminas para Arcelor | B33: BOQ0575LA1150 | D33: NBR-6656-16-LNE-500 | E33: 20 | F33: 115000 | G33: DIADEMA | H33: DE: USIMINAS PARA: ARCELOR | J33: 5.75 | K33: MTH (+0,25mm) | L33: MTL (-0,25mm) | N33: N/A | O33: N/A | Q33: N/A | R33: N/A | T33: 1150 | U33: N/A | V33: N/A | W33: N/A | Y33: 46118 | Z33: SIM | AA33: 46120 | AB33: 46150 | AC33: 46127 | AD33: VIÁVEL | AE33: N/A | AF33: N/A | AG33: 46266 | AH33: 46266 | AI33: VERIFICAR PROGRAMAÇÃO | AJ33: LOGÍSTICA - PROGRAMAÇÃO | AK33: ENVIADO CONFIRMAÇÃO PARA ENG.
A34: 27 - Redução consumo MTP aplicando tolerância mínima curva B | B34: SLZ0080UL0625 | C34: Mean to-low Curva B | D34: VW50065-CR2-GI40/40-U | E34: 16.49648 | F34: 27611.065 | G34: JARINU | H34: S.U | J34: 0.8 | K34: ±0,04 | L34: -0,02 / +0,00 PROPOSTA DELGA +0,00 / -0,04 - PROPOSTA USINA | N34: N/A | O34: N/A | Q34: N/A | R34: N/A | T34: N/A | U34: N/A | V34: N/A | W34: N/A | Y34: Data não informada. | Z34: SIM | AA34: 46093 | AB34: 46108 | AC34: 46155 | AD34: VIÁVEL | AE34: 46231 | AF34: 46248 | AG34: 46174 | AH34: 46174 | AI34: 46285 | AJ34: USINA - EM PRODUÇÃO | AK34: ITEM ENVIADO NO PRIMEIRO PACOTE DE SOLICITAÇÕES DE MODIFICAÇÕES
A35: 27 - Redução consumo MTP aplicando tolerância mínima curva B | B35: SLZ0120SM0525 | C35: Mean to-low Curva B | D35: VW50065CR240LA-GI40/40U | E35: 10.200945 | F35: =13937.7508231501+12721.88 -> 26659.631 | G35: JARINU | H35: S.U | J35: 1.2 | K35: ±0,055 | L35: -0,0275 / +0,00 | N35: N/A | O35: N/A | Q35: N/A | R35: N/A | T35: 525 | U35: 515 | V35: 140 | W35: 140 | Y35: Data não informada. | Z35: SIM | AA35: 46199 | AB35: INVIÁVEL | AC35: INVIÁVEL | AD35: INVIÁVEL | AE35: INVIÁVEL | AF35: INVIÁVEL | AG35: INVIÁVEL | AH35: INVIÁVEL | AI35: INVIÁVEL | AJ35: INVIÁVEL | AK35: INVIÁVEL
A36: 27 - Redução consumo MTP aplicando tolerância mínima curva B | B36: SLZ0070QH0550 | C36: Mean to-low Curva B | D36: VW50065CR4GI40/40-U-O | E36: 13.94008 | F36: 26601.635 | G36: JARINU | H36: S.U | J36: 0.7 | K36: ±0,04 | L36: -0,02 / +0,00 | N36: N/A | O36: N/A | Q36: N/A | R36: N/A | T36: N/A | U36: N/A | V36: N/A | W36: N/A | Y36: Data não informada. | Z36: SIM | AA36: 46199 | AB36: INVIÁVEL | AC36: INVIÁVEL | AD36: INVIÁVEL | AE36: INVIÁVEL | AF36: INVIÁVEL | AG36: INVIÁVEL | AH36: INVIÁVEL | AI36: INVIÁVEL | AJ36: INVIÁVEL | AK36: INVIÁVEL
A37: 27 - Redução consumo MTP aplicando tolerância mínima curva B | B37: SLZ0165TH0520 | C37: Mean to-low Curva B | D37: VW50065CR380LAGI40/40-UC-U-O | E37: 10.848305 | F37: 20698.992 | G37: JARINU | H37: S.U | J37: 1.65 | K37: ±0,085 | L37: -0,04 / +0,00 | N37: N/A | O37: N/A | Q37: N/A | R37: N/A | T37: N/A | U37: N/A | V37: N/A | W37: N/A | Y37: Data não informada. | Z37: SIM | AA37: 46199 | AB37: 46245 | AC37: 46260 | AD37: VIÁVEL | AE37: 46294 | AF37: 46294 | AG37: 46294 | AH37: 46311 | AI37: 46456 | AJ37: USINA - EM PRODUÇÃO | AK37: RESPOSTA CONSULTA METALÚRGICA DEVOLVIDA 26/08 - AGUARDANDO VALIDAÇÃO DA ENGENHARIA
